<?xml version="1.0"?>
<robot name="test_robot">
  <link name="base_link">
    <visual>
      <geometry>
        <cylinder length="0.1" radius="0.1" />
      </geometry>
    </visual>
  </link>

  <link name="link2">
    <visual>
      <geometry>
        <box size="0.08 0.01 0.01" />
      </geometry>
    </visual>
  </link>

  <link name="link3" >
    <visual>
      <geometry>
        <sphere radius="0.08"/>
      </geometry>
    </visual>
  </link>

  <link name="link4" >
    <visual>
      <origin rpy="0 -1.57 0" xyz="1 0 0"/>
      <geometry>
        <cylinder length="0.08" radius="0.08" />
      </geometry>
    </visual>
  </link>


  <joint name="joint1" type="fixed">
    <parent link="base_link"/>
    <child link="link2"/>
    <origin xyz="0.22 0 0.6" rpy="0 1.57 0" />
  </joint>

  <joint name="joint2" type="continuous">
    <parent link="base_link"/>
    <child link="link3"/>
    <origin xyz="-0.1 0.5 0" />
  </joint>

  <joint name="joint3" type="fixed">
    <parent link="link3"/>
    <child link="link4"/>
    <origin xyz=".5 0 0" rpy="0 0 -1.57" />
  </joint>
</robot>
