<?xml version="1.0"?>
<robot name="test_robot">
  <link name="base_link" />
  <link name="link2" />
  <link name="link3" />
  <link name="link4" />


  <joint name="joint1" type="continuous">
    <parent link="base_link"/>
    <child link="link2"/>
    <origin xyz=".5 .3 0.7" rpy="0 0 0" />
  </joint>

  <joint name="joint2" type="continuous">
    <parent link="base_link"/>
    <child link="link3"/>
    <origin xyz="-.2 .5 -0.3" rpy="0 0 1.57" />
  </joint>

  <joint name="joint3" type="continuous">
    <parent link="link3"/>
    <child link="link4"/>
    <origin xyz=".5 0 0.2" rpy="0 0 -1.57" />
  </joint>
</robot>
